Workbook

Sheet Q1
C2: MINISTERIO DE SALUD PÚBLICA Y ASISTENCIA SOCIAL
C3: Hospital de Tecpán
C4: Hoja de Control de Quirófanos
B6: QUIRÓFANO #1 | AH6: Formato | AI6: Estado_Cirugia | AJ6: Procedimientos | AK6: Rangos | AL6: Procedencia
B7: Encargado | AH7: Abierta | AI7: Finalizada | AJ7: Cirugía Cardiovascular - Angioplastia coronaria | AK7: Especialista | AL7: Emergencia
B8: Uso | AH8: Videolaparoscópica | AI8: Cancelada | AJ8: Cirugía Cardiovascular - Bypass coronario | AK8: Médico General | AL8: Electiva
B9: Hora de apertura de quirófano | AH9: Endoscópica | AJ9: Cirugía Cardiovascular - Cirugía de aorta torácica | AK9: R1 | AL9: Hospital de día
B10: Hora de cierre de quirófano | AH10: Artroscópica | AJ10: Cirugía Cardiovascular - Cirugía vascular periférica | AK10: R2
B11: Cantidad de días en que está abierto | AH11: Percutánea | AJ11: Cirugía Cardiovascular - Endarterectomía carotídea | AK11: R3
AH12: Endourológica | AJ12: Cirugía Cardiovascular - Implantación de marcapasos | AK12: R3
A13: No | B13: Fecha | C13: Nombre del Paciente | D13: Rango del Médico | E13: Especialidad del Médico | F13: Nombre del Médico | G13: Procedencia paciente | H13: Formato de Intervención | I13: Procedimiento #1 (Principal) | J13: Procedimiento #2 | K13: Procedimiento #3 | L13: Procedimiento #4 | M13: Procedimiento #5 | N13: Área del cuerpo intervenida | O13: Observaciones / Comentarios | P13: Hora de inicio de anestesia | Q13: Hora de inicio de intervención (es) | R13: Hora de finalización de intervención quirúrgica | S13: Hora de finalización limpieza y preparación de quirófano | T13: Tiempo Intervención | U13: Tiempo Usado Quirófano | V13: Estado | AH13: Vaginal | AJ13: Cirugía Cardiovascular - Pericardiocentesis quirúrgica | AK13: R4 | AM13: TOTAL_PROCEDIMIENTOS
A14: 1 | T14: =R14-Q14 | U14: =S14-Q14 | W14: =S14-R14 | Z14: Horas Activo | AB14: % de Uso Periodo | AD14: Tasa de Cancelación | AH14: Mixta | AJ14: Cirugía Cardiovascular - Reemplazo valvular | AM14: =_xlfn.TEXTJOIN(" + ", TRUE, I14:M14)
A15: 2 | T15: =R15-Q15 | U15: =S15-Q15 | W15: =S15-R15 | Z15: =D10-D9 | AB15: =SUMIF(V14:V613,"Finalizada",U14:U613)/Z18 | AD15: =AB22/(Z22+AB22) | AH15: Otro | AJ15: Cirugía Cardiovascular - Reparación de aneurismas | AM15: =_xlfn.TEXTJOIN(" + ", TRUE, I15:M15)
A16: 3 | T16: =R16-Q16 | U16: =S16-Q16 | W16: =S16-R16 | AJ16: Cirugía Cardiovascular - Reparación valvular | AM16: =_xlfn.TEXTJOIN(" + ", TRUE, I16:M16)
A17: 4 | T17: =R17-Q17 | U17: =S17-Q17 | W17: =S17-R17 | Z17: Horas Activo Periodo | AJ17: Cirugía Cardiovascular - Trasplante cardíaco | AM17: =_xlfn.TEXTJOIN(" + ", TRUE, I17:M17)
A18: 5 | T18: =R18-Q18 | U18: =S18-Q18 | W18: =S18-R18 | Z18: =(D10-D9)*D11 | AJ18: Cirugía de Emergencia - Amputación de urgencia | AM18: =_xlfn.TEXTJOIN(" + ", TRUE, I18:M18)
A19: 6 | T19: =R19-Q19 | U19: =S19-Q19 | W19: =S19-R19 | AJ19: Cirugía de Emergencia - Cesárea de emergencia | AM19: =_xlfn.TEXTJOIN(" + ", TRUE, I19:M19)
A20: 7 | T20: =R20-Q20 | U20: =S20-Q20 | W20: =S20-R20 | AJ20: Cirugía de Emergencia - Control de daños | AM20: =_xlfn.TEXTJOIN(" + ", TRUE, I20:M20)
A21: 8 | T21: =R21-Q21 | U21: =S21-Q21 | W21: =S21-R21 | Z21: Finalizadas | AB21: Canceladas | AJ21: Cirugía de Emergencia - Control de hemorragias | AM21: =_xlfn.TEXTJOIN(" + ", TRUE, I21:M21)
A22: 9 | T22: =R22-Q22 | U22: =S22-Q22 | W22: =S22-R22 | Z22: =COUNTIF($V$14:$V$613,"Finalizada") | AB22: =COUNTIF($V$14:$V$613,"Cancelada") | AJ22: Cirugía de Emergencia - Craniectomía descompresiva | AM22: =_xlfn.TEXTJOIN(" + ", TRUE, I22:M22)
A23: 10 | T23: =R23-Q23 | U23: =S23-Q23 | W23: =S23-R23 | AJ23: Cirugía de Emergencia - Desbridamiento de tejidos infectados | AM23: =_xlfn.TEXTJOIN(" + ", TRUE, I23:M23)
A24: 11 | T24: =R24-Q24 | U24: =S24-Q24 | W24: =S24-R24 | Z24: Total | AJ24: Cirugía de Emergencia - Drenaje de abscesos profundos | AM24: =_xlfn.TEXTJOIN(" + ", TRUE, I24:M24)
A25: 12 | T25: =R25-Q25 | U25: =S25-Q25 | W25: =S25-R25 | Z25: =COUNTA(V14:V613) | AJ25: Cirugía de Emergencia - Fasciotomía urgente | AM25: =_xlfn.TEXTJOIN(" + ", TRUE, I25:M25)
A26: 13 | T26: =R26-Q26 | U26: =S26-Q26 | W26: =S26-R26 | AJ26: Cirugía de Emergencia - Laparotomía de urgencia | AM26: =_xlfn.TEXTJOIN(" + ", TRUE, I26:M26)
A27: 14 | T27: =R27-Q27 | U27: =S27-Q27 | W27: =S27-R27 | AJ27: Cirugía de Emergencia - Toracotomía de emergencia | AM27: =_xlfn.TEXTJOIN(" + ", TRUE, I27:M27)
A28: 15 | T28: =R28-Q28 | U28: =S28-Q28 | W28: =S28-R28 | Z28: Tiempo Promedio Intervención | AC28: Tiempo Promedio Limpieza y Preparación | AJ28: Cirugía General - (VAC) Cambio de terapia de presión negativa | AM28: =_xlfn.TEXTJOIN(" + ", TRUE, I28:M28)
A29: 16 | T29: =R29-Q29 | U29: =S29-Q29 | W29: =S29-R29 | Z29: =AVERAGEIF(T14:T613,"<>0") | AC29: =AVERAGEIF(W14:W613,"<>0") | AJ29: Cirugía General - (VAC) Colocación de terapia de presión negativa | AM29: =_xlfn.TEXTJOIN(" + ", TRUE, I29:M29)
A30: 17 | T30: =R30-Q30 | U30: =S30-Q30 | W30: =S30-R30 | AJ30: Cirugía General - (VAC) Retiro de terapia de presión negativa | AM30: =_xlfn.TEXTJOIN(" + ", TRUE, I30:M30)
A31: 18 | T31: =R31-Q31 | U31: =S31-Q31 | W31: =S31-R31 | Z31: Tiempo Promedio Proceso Completo | AJ31: Cirugía General - Adhesiolisis | AM31: =_xlfn.TEXTJOIN(" + ", TRUE, I31:M31)
A32: 19 | T32: =R32-Q32 | U32: =S32-Q32 | W32: =S32-R32 | Z32: =AVERAGEIF(U14:U613,"<>0") | AJ32: Cirugía General - Amputación | AM32: =_xlfn.TEXTJOIN(" + ", TRUE, I32:M32)
A33: 20 | T33: =R33-Q33 | U33: =S33-Q33 | W33: =S33-R33 | AJ33: Cirugía General - Anastomosis intestinal | AM33: =_xlfn.TEXTJOIN(" + ", TRUE, I33:M33)
A34: 21 | T34: =R34-Q34 | U34: =S34-Q34 | W34: =S34-R34 | AJ34: Cirugía General - Apendicectomía | AM34: =_xlfn.TEXTJOIN(" + ", TRUE, I34:M34)
A35: 22 | T35: =R35-Q35 | U35: =S35-Q35 | W35: =S35-R35 | AJ35: Cirugía General - Biopsia excisional | AM35: =_xlfn.TEXTJOIN(" + ", TRUE, I35:M35)
A36: 23 | T36: =R36-Q36 | U36: =S36-Q36 | W36: =S36-R36 | AJ36: Cirugía General - Biopsia quirúrgica | AM36: =_xlfn.TEXTJOIN(" + ", TRUE, I36:M36)
A37: 24 | T37: =R37-Q37 | U37: =S37-Q37 | W37: =S37-R37 | AJ37: Cirugía General - Bypass gástrico | AM37: =_xlfn.TEXTJOIN(" + ", TRUE, I37:M37)
A38: 25 | T38: =R38-Q38 | U38: =S38-Q38 | W38: =S38-R38 | AJ38: Cirugía General - Cierre de herida | AM38: =_xlfn.TEXTJOIN(" + ", TRUE, I38:M38)
A39: 26 | T39: =R39-Q39 | U39: =S39-Q39 | W39: =S39-R39 | AJ39: Cirugía General - Cierre de ostomías | AM39: =_xlfn.TEXTJOIN(" + ", TRUE, I39:M39)
A40: 27 | T40: =R40-Q40 | U40: =S40-Q40 | W40: =S40-R40 | AJ40: Cirugía General - Cirugía de diverticulitis | AM40: =_xlfn.TEXTJOIN(" + ", TRUE, I40:M40)
A41: 28 | T41: =R41-Q41 | U41: =S41-Q41 | W41: =S41-R41 | AJ41: Cirugía General - Cirugía de quistes hepáticos | AM41: =_xlfn.TEXTJOIN(" + ", TRUE, I41:M41)
A42: 29 | T42: =R42-Q42 | U42: =S42-Q42 | W42: =S42-R42 | AJ42: Cirugía General - Cirugía de quistes sebáceos | AM42: =_xlfn.TEXTJOIN(" + ", TRUE, I42:M42)
...

Sheet Q2
C2: MINISTERIO DE SALUD PÚBLICA Y ASISTENCIA SOCIAL
C3: ='Q1'!C3
C4: Hoja de Control de Quirófanos
B6: QUIRÓFANO #2 | AH6: Formato | AI6: Estado_Cirugia | AJ6: Procedimientos | AK6: Rangos | AL6: Procedencia
B7: Encargado | AH7: Abierta | AI7: Finalizada | AJ7: Cirugía Cardiovascular - Angioplastia coronaria | AK7: Especialista | AL7: Emergencia
B8: Uso | AH8: Videolaparoscópica | AI8: Cancelada | AJ8: Cirugía Cardiovascular - Bypass coronario | AK8: Médico General | AL8: Electiva
B9: Hora de apertura de quirófano | AH9: Endoscópica | AJ9: Cirugía Cardiovascular - Cirugía de aorta torácica | AK9: R1 | AL9: Hospital de día
B10: Hora de cierre de quirófano | AH10: Artroscópica | AJ10: Cirugía Cardiovascular - Cirugía vascular periférica | AK10: R2
B11: Cantidad de días en que está abierto | AH11: Percutánea | AJ11: Cirugía Cardiovascular - Endarterectomía carotídea | AK11: R3
AH12: Endourológica | AJ12: Cirugía Cardiovascular - Implantación de marcapasos | AK12: R3
A13: No | B13: Fecha | C13: Nombre del Paciente | D13: Rango del Médico | E13: Especialidad del Médico | F13: Nombre del Médico | G13: Procedencia paciente | H13: Formato de Intervención | I13: Procedimiento #1 (Principal) | J13: Procedimiento #2 | K13: Procedimiento #3 | L13: Procedimiento #4 | M13: Procedimiento #5 | N13: Área del cuerpo intervenida | O13: Observaciones / Comentarios | P13: Hora de inicio de anestesia | Q13: Hora de inicio de intervención (es) | R13: Hora de finalización de intervención quirúrgica | S13: Hora de finalización limpieza y preparación de quirófano | T13: Tiempo Intervención | U13: Tiempo Usado Quirófano | V13: Estado | AH13: Vaginal | AJ13: Cirugía Cardiovascular - Pericardiocentesis quirúrgica | AK13: R4 | AM13: TOTAL_PROCEDIMIENTOS
T14: =R14-Q14 | U14: =S14-Q14 | W14: =S14-R14 | Z14: Horas Activo | AB14: % de Uso Periodo | AD14: Tasa de Cancelación | AH14: Mixta | AJ14: Cirugía Cardiovascular - Reemplazo valvular | AM14: =_xlfn.TEXTJOIN(" + ", TRUE, I14:M14)
T15: =R15-Q15 | U15: =S15-Q15 | W15: =S15-R15 | Z15: =D10-D9 | AB15: =SUMIF(V14:V613,"Finalizada",U14:U613)/Z18 | AD15: =AB22/(Z22+AB22) | AH15: Otro | AJ15: Cirugía Cardiovascular - Reparación de aneurismas | AM15: =_xlfn.TEXTJOIN(" + ", TRUE, I15:M15)
T16: =R16-Q16 | U16: =S16-Q16 | W16: =S16-R16 | AJ16: Cirugía Cardiovascular - Reparación valvular | AM16: =_xlfn.TEXTJOIN(" + ", TRUE, I16:M16)
T17: =R17-Q17 | U17: =S17-Q17 | W17: =S17-R17 | Z17: Horas Activo Periodo | AJ17: Cirugía Cardiovascular - Trasplante cardíaco | AM17: =_xlfn.TEXTJOIN(" + ", TRUE, I17:M17)
T18: =R18-Q18 | U18: =S18-Q18 | W18: =S18-R18 | Z18: =(D10-D9)*D11 | AJ18: Cirugía de Emergencia - Amputación de urgencia | AM18: =_xlfn.TEXTJOIN(" + ", TRUE, I18:M18)
T19: =R19-Q19 | U19: =S19-Q19 | W19: =S19-R19 | AJ19: Cirugía de Emergencia - Cesárea de emergencia | AM19: =_xlfn.TEXTJOIN(" + ", TRUE, I19:M19)
T20: =R20-Q20 | U20: =S20-Q20 | W20: =S20-R20 | AJ20: Cirugía de Emergencia - Control de daños | AM20: =_xlfn.TEXTJOIN(" + ", TRUE, I20:M20)
T21: =R21-Q21 | U21: =S21-Q21 | W21: =S21-R21 | Z21: Finalizadas | AB21: Canceladas | AJ21: Cirugía de Emergencia - Control de hemorragias | AM21: =_xlfn.TEXTJOIN(" + ", TRUE, I21:M21)
T22: =R22-Q22 | U22: =S22-Q22 | W22: =S22-R22 | Z22: =COUNTIF($V$14:$V$613,"Finalizada") | AB22: =COUNTIF($V$14:$V$613,"Cancelada") | AJ22: Cirugía de Emergencia - Craniectomía descompresiva | AM22: =_xlfn.TEXTJOIN(" + ", TRUE, I22:M22)
T23: =R23-Q23 | U23: =S23-Q23 | W23: =S23-R23 | AJ23: Cirugía de Emergencia - Desbridamiento de tejidos infectados | AM23: =_xlfn.TEXTJOIN(" + ", TRUE, I23:M23)
T24: =R24-Q24 | U24: =S24-Q24 | W24: =S24-R24 | Z24: Total | AJ24: Cirugía de Emergencia - Drenaje de abscesos profundos | AM24: =_xlfn.TEXTJOIN(" + ", TRUE, I24:M24)
T25: =R25-Q25 | U25: =S25-Q25 | W25: =S25-R25 | Z25: =COUNTA(V14:V613) | AJ25: Cirugía de Emergencia - Fasciotomía urgente | AM25: =_xlfn.TEXTJOIN(" + ", TRUE, I25:M25)
T26: =R26-Q26 | U26: =S26-Q26 | W26: =S26-R26 | AJ26: Cirugía de Emergencia - Laparotomía de urgencia | AM26: =_xlfn.TEXTJOIN(" + ", TRUE, I26:M26)
T27: =R27-Q27 | U27: =S27-Q27 | W27: =S27-R27 | AJ27: Cirugía de Emergencia - Toracotomía de emergencia | AM27: =_xlfn.TEXTJOIN(" + ", TRUE, I27:M27)
T28: =R28-Q28 | U28: =S28-Q28 | W28: =S28-R28 | Z28: Tiempo Promedio Intervención | AC28: Tiempo Promedio Limpieza | AJ28: Cirugía General - (VAC) Cambio de terapia de presión negativa | AM28: =_xlfn.TEXTJOIN(" + ", TRUE, I28:M28)
T29: =R29-Q29 | U29: =S29-Q29 | W29: =S29-R29 | Z29: =AVERAGEIF(T14:T613,"<>0") | AC29: =AVERAGEIF(W14:W613,"<>0") | AJ29: Cirugía General - (VAC) Colocación de terapia de presión negativa | AM29: =_xlfn.TEXTJOIN(" + ", TRUE, I29:M29)
T30: =R30-Q30 | U30: =S30-Q30 | W30: =S30-R30 | AJ30: Cirugía General - (VAC) Retiro de terapia de presión negativa | AM30: =_xlfn.TEXTJOIN(" + ", TRUE, I30:M30)
T31: =R31-Q31 | U31: =S31-Q31 | W31: =S31-R31 | Z31: Tiempo Promedio Proceso Completo | AJ31: Cirugía General - Adhesiolisis | AM31: =_xlfn.TEXTJOIN(" + ", TRUE, I31:M31)
T32: =R32-Q32 | U32: =S32-Q32 | W32: =S32-R32 | Z32: =AVERAGEIF(U14:U613,"<>0") | AJ32: Cirugía General - Amputación | AM32: =_xlfn.TEXTJOIN(" + ", TRUE, I32:M32)
T33: =R33-Q33 | U33: =S33-Q33 | W33: =S33-R33 | AJ33: Cirugía General - Anastomosis intestinal | AM33: =_xlfn.TEXTJOIN(" + ", TRUE, I33:M33)
T34: =R34-Q34 | U34: =S34-Q34 | W34: =S34-R34 | AJ34: Cirugía General - Apendicectomía | AM34: =_xlfn.TEXTJOIN(" + ", TRUE, I34:M34)
T35: =R35-Q35 | U35: =S35-Q35 | W35: =S35-R35 | AJ35: Cirugía General - Biopsia excisional | AM35: =_xlfn.TEXTJOIN(" + ", TRUE, I35:M35)
T36: =R36-Q36 | U36: =S36-Q36 | W36: =S36-R36 | AJ36: Cirugía General - Biopsia quirúrgica | AM36: =_xlfn.TEXTJOIN(" + ", TRUE, I36:M36)
T37: =R37-Q37 | U37: =S37-Q37 | W37: =S37-R37 | AJ37: Cirugía General - Bypass gástrico | AM37: =_xlfn.TEXTJOIN(" + ", TRUE, I37:M37)
T38: =R38-Q38 | U38: =S38-Q38 | W38: =S38-R38 | AJ38: Cirugía General - Cierre de herida | AM38: =_xlfn.TEXTJOIN(" + ", TRUE, I38:M38)
T39: =R39-Q39 | U39: =S39-Q39 | W39: =S39-R39 | AJ39: Cirugía General - Cierre de ostomías | AM39: =_xlfn.TEXTJOIN(" + ", TRUE, I39:M39)
T40: =R40-Q40 | U40: =S40-Q40 | W40: =S40-R40 | AJ40: Cirugía General - Cirugía de diverticulitis | AM40: =_xlfn.TEXTJOIN(" + ", TRUE, I40:M40)
T41: =R41-Q41 | U41: =S41-Q41 | W41: =S41-R41 | AJ41: Cirugía General - Cirugía de quistes hepáticos | AM41: =_xlfn.TEXTJOIN(" + ", TRUE, I41:M41)
T42: =R42-Q42 | U42: =S42-Q42 | W42: =S42-R42 | AJ42: Cirugía General - Cirugía de quistes sebáceos | AM42: =_xlfn.TEXTJOIN(" + ", TRUE, I42:M42)
...

Sheet Resumen
C2: MINISTERIO DE SALUD PÚBLICA Y ASISTENCIA SOCIAL
C3: ='Q1'!C3
C4: Resumen Mensual | Q4: 1 | R4: ='Q1'!AM14
R5: ='Q1'!AM15
R6: ='Q1'!AM16
A7: Cantidad | B7: Intervención | C7: Tiempo Promedio | E7: % de Uso Periodo | G7: Tasa de Cancelación | R7: ='Q1'!AM17
A8: =IF(B8="","",COUNTIF($R$4:$R$1203,B8)) | B8: {=_xlfn.UNIQUE(_xlfn._xlws.FILTER($R$4:$R$1203,($R$4:$R$1203<>"")*($R$4:$R$1203<>0)))} | C8: =IFERROR( ( SUMIF('Q1'!$AM$14:$AM$613,B8,'Q1'!$T$14:$T$613) +SUMIF('Q2'!$AM$14:$AM$613,B8,'Q2'!$T$14:$T$613) ) /A8,"") | E8: =IFERROR( ( SUMIF('Q1'!V14:V613,"Finalizada",'Q1'!U14:U613) +SUMIF('Q2'!V14:V613,"Finalizada",'Q2'!U14:U613) ) / ( 'Q1'!Z18+'Q2'!Z18 ),0) | G8: =IFERROR( ( COUNTIF('Q1'!V14:V613,"Cancelada") +COUNTIF('Q2'!V14:V613,"Cancelada") ) / ( COUNTIF('Q1'!V14:V613,"Finalizada")+COUNTIF('Q1'!V14:V613,"Cancelada")+COUNTIF('Q1'!V14:V613,"Reprogramada") +COUNTIF('Q2'!V14:V613,"Finalizada")+COUNTIF('Q2'!V14:V613,"Cancelada")+COUNTIF('Q2'!V14:V613,"Reprogramada") ),0) | R8: ='Q1'!AM18
A9: =IF(B9="","",COUNTIF($R$4:$R$4803,B9)) | C9: =IFERROR( ( SUMIF('Q1'!$AM$14:$AM$613,B9,'Q1'!$T$14:$T$613) +SUMIF('Q2'!$AM$14:$AM$613,B9,'Q2'!$T$14:$T$613) ) /A9,"") | R9: ='Q1'!AM19
A10: =IF(B10="","",COUNTIF($R$4:$R$4803,B10)) | C10: =IFERROR( ( SUMIF('Q1'!$AM$14:$AM$613,B10,'Q1'!$T$14:$T$613) +SUMIF('Q2'!$AM$14:$AM$613,B10,'Q2'!$T$14:$T$613) ) /A10,"") | E10: Finalizadas | G10: Canceladas | R10: ='Q1'!AM20
A11: =IF(B11="","",COUNTIF($R$4:$R$4803,B11)) | C11: =IFERROR( ( SUMIF('Q1'!$AM$14:$AM$613,B11,'Q1'!$T$14:$T$613) +SUMIF('Q2'!$AM$14:$AM$613,B11,'Q2'!$T$14:$T$613) ) /A11,"") | E11: ='Q1'!Z22+'Q2'!Z22 | G11: ='Q1'!AB22+'Q2'!AB22 | R11: ='Q1'!AM21
A12: =IF(B12="","",COUNTIF($R$4:$R$4803,B12)) | C12: =IFERROR( ( SUMIF('Q1'!$AM$14:$AM$613,B12,'Q1'!$T$14:$T$613) +SUMIF('Q2'!$AM$14:$AM$613,B12,'Q2'!$T$14:$T$613) ) /A12,"") | R12: ='Q1'!AM22
A13: =IF(B13="","",COUNTIF($R$4:$R$4803,B13)) | C13: =IFERROR( ( SUMIF('Q1'!$AM$14:$AM$613,B13,'Q1'!$T$14:$T$613) +SUMIF('Q2'!$AM$14:$AM$613,B13,'Q2'!$T$14:$T$613) ) /A13,"") | E13: Total | R13: ='Q1'!AM23
A14: =IF(B14="","",COUNTIF($R$4:$R$4803,B14)) | C14: =IFERROR( ( SUMIF('Q1'!$AM$14:$AM$613,B14,'Q1'!$T$14:$T$613) +SUMIF('Q2'!$AM$14:$AM$613,B14,'Q2'!$T$14:$T$613) ) /A14,"") | E14: =E11+G11+I11 | R14: ='Q1'!AM24
A15: =IF(B15="","",COUNTIF($R$4:$R$4803,B15)) | C15: =IFERROR( ( SUMIF('Q1'!$AM$14:$AM$613,B15,'Q1'!$T$14:$T$613) +SUMIF('Q2'!$AM$14:$AM$613,B15,'Q2'!$T$14:$T$613) ) /A15,"") | R15: ='Q1'!AM25
A16: =IF(B16="","",COUNTIF($R$4:$R$4803,B16)) | C16: =IFERROR( ( SUMIF('Q1'!$AM$14:$AM$613,B16,'Q1'!$T$14:$T$613) +SUMIF('Q2'!$AM$14:$AM$613,B16,'Q2'!$T$14:$T$613) ) /A16,"") | E16: Tiempo Promedio Intervención General | R16: ='Q1'!AM26
A17: =IF(B17="","",COUNTIF($R$4:$R$4803,B17)) | C17: =IFERROR( ( SUMIF('Q1'!$AM$14:$AM$613,B17,'Q1'!$T$14:$T$613) +SUMIF('Q2'!$AM$14:$AM$613,B17,'Q2'!$T$14:$T$613) ) /A17,"") | E17: =AVERAGEIF(C8:C500,">0") | R17: ='Q1'!AM27
A18: =IF(B18="","",COUNTIF($R$4:$R$4803,B18)) | C18: =IFERROR( ( SUMIF('Q1'!$AM$14:$AM$613,B18,'Q1'!$T$14:$T$613) +SUMIF('Q2'!$AM$14:$AM$613,B18,'Q2'!$T$14:$T$613) ) /A18,"") | R18: ='Q1'!AM28
A19: =IF(B19="","",COUNTIF($R$4:$R$4803,B19)) | C19: =IFERROR( ( SUMIF('Q1'!$AM$14:$AM$613,B19,'Q1'!$T$14:$T$613) +SUMIF('Q2'!$AM$14:$AM$613,B19,'Q2'!$T$14:$T$613) ) /A19,"") | R19: ='Q1'!AM29
A20: =IF(B20="","",COUNTIF($R$4:$R$4803,B20)) | C20: =IFERROR( ( SUMIF('Q1'!$AM$14:$AM$613,B20,'Q1'!$T$14:$T$613) +SUMIF('Q2'!$AM$14:$AM$613,B20,'Q2'!$T$14:$T$613) ) /A20,"") | R20: ='Q1'!AM30
A21: =IF(B21="","",COUNTIF($R$4:$R$4803,B21)) | C21: =IFERROR( ( SUMIF('Q1'!$AM$14:$AM$613,B21,'Q1'!$T$14:$T$613) +SUMIF('Q2'!$AM$14:$AM$613,B21,'Q2'!$T$14:$T$613) ) /A21,"") | R21: ='Q1'!AM31
A22: =IF(B22="","",COUNTIF($R$4:$R$4803,B22)) | C22: =IFERROR( ( SUMIF('Q1'!$AM$14:$AM$613,B22,'Q1'!$T$14:$T$613) +SUMIF('Q2'!$AM$14:$AM$613,B22,'Q2'!$T$14:$T$613) ) /A22,"") | R22: ='Q1'!AM32
A23: =IF(B23="","",COUNTIF($R$4:$R$4803,B23)) | C23: =IFERROR( ( SUMIF('Q1'!$AM$14:$AM$613,B23,'Q1'!$T$14:$T$613) +SUMIF('Q2'!$AM$14:$AM$613,B23,'Q2'!$T$14:$T$613) ) /A23,"") | R23: ='Q1'!AM33
A24: =IF(B24="","",COUNTIF($R$4:$R$4803,B24)) | C24: =IFERROR( ( SUMIF('Q1'!$AM$14:$AM$613,B24,'Q1'!$T$14:$T$613) +SUMIF('Q2'!$AM$14:$AM$613,B24,'Q2'!$T$14:$T$613) ) /A24,"") | R24: ='Q1'!AM34
A25: =IF(B25="","",COUNTIF($R$4:$R$4803,B25)) | C25: =IFERROR( ( SUMIF('Q1'!$AM$14:$AM$613,B25,'Q1'!$T$14:$T$613) +SUMIF('Q2'!$AM$14:$AM$613,B25,'Q2'!$T$14:$T$613) ) /A25,"") | R25: ='Q1'!AM35
A26: =IF(B26="","",COUNTIF($R$4:$R$4803,B26)) | C26: =IFERROR( ( SUMIF('Q1'!$AM$14:$AM$613,B26,'Q1'!$T$14:$T$613) +SUMIF('Q2'!$AM$14:$AM$613,B26,'Q2'!$T$14:$T$613) ) /A26,"") | R26: ='Q1'!AM36
A27: =IF(B27="","",COUNTIF($R$4:$R$4803,B27)) | C27: =IFERROR( ( SUMIF('Q1'!$AM$14:$AM$613,B27,'Q1'!$T$14:$T$613) +SUMIF('Q2'!$AM$14:$AM$613,B27,'Q2'!$T$14:$T$613) ) /A27,"") | R27: ='Q1'!AM37
A28: =IF(B28="","",COUNTIF($R$4:$R$4803,B28)) | C28: =IFERROR( ( SUMIF('Q1'!$AM$14:$AM$613,B28,'Q1'!$T$14:$T$613) +SUMIF('Q2'!$AM$14:$AM$613,B28,'Q2'!$T$14:$T$613) ) /A28,"") | R28: ='Q1'!AM38
A29: =IF(B29="","",COUNTIF($R$4:$R$4803,B29)) | C29: =IFERROR( ( SUMIF('Q1'!$AM$14:$AM$613,B29,'Q1'!$T$14:$T$613) +SUMIF('Q2'!$AM$14:$AM$613,B29,'Q2'!$T$14:$T$613) ) /A29,"") | R29: ='Q1'!AM39
... A500: =IF(B500="","",COUNTIF($R$4:$R$4803,B500)) | C500: =IFERROR( ( SUMIF('Q1'!$AM$14:$AM$613,B500,'Q1'!$T$14:$T$613) +SUMIF('Q2'!$AM$14:$AM$613,B500,'Q2'!$T$14:$T$613) ) /A500,"") | R500: ='Q1'!AM510
R501: ='Q1'!AM511
R502: ='Q1'!AM512
R503: ='Q1'!AM513
R504: ='Q1'!AM514
R505: ='Q1'!AM515
R506: ='Q1'!AM516
R507: ='Q1'!AM517
R508: ='Q1'!AM518
R509: ='Q1'!AM519
R510: ='Q1'!AM520
R511: ='Q1'!AM521
...
